Workbook

Sheet Cách đọc file
A1: MỞ TAB NÀO ĐỂ LÀM GÌ
A2: Tên tab | B2: Dùng để
A3: Kế hoạch chèn link | B3: Xem nhanh. Mỗi trang đích là 1 dòng. Kéo sang phải sẽ thấy từng cặp: Anchortext + URL bài đặt link.
A4: Tổng hợp 75 trang đích | B4: Xem chi tiết. Mỗi link là 1 dòng. Ô xám bên trái ghi mỗi trang đích có bao nhiêu link và anchor nào dùng mấy lần.
A5: Link đi từ bài nào | B5: Xem ngược lại: một bài blog sẽ đặt link sang những trang đích nào.
A6: Inlink đã chèn | B6: Các link đang có sẵn trên web.
A7: Inlink - Đề xuất 5 bài/ trang đích, 3 link/ nguồn | B7: Bản rút gọn cũ, chỉ để so sánh.
A8: Ý nghĩa màu | B8: Xanh lá = nên chèn trước. Xanh dương = chèn được. Vàng = cần đọc lại bài rồi mới chèn. Cam (chữ đậm) = anchor ưu tiên sếp giao ở tab Trang tính3.
A9: Lưu ý | B9: Mức độ phù hợp dựa trên tiêu đề và mô tả bài, chưa đọc nội dung bài.
A10: Anchor | B10: 18 trang có trong tab Trang tính3 dùng đúng danh sách anchor của sếp (đã dùng hết từng anchor). 57 trang còn lại dùng anchor theo từ khoá chính của trang.
A11: Số link mỗi trang | B11: Đã chỉnh cho khớp cột "Số inlink mục tiêu" (cột E tab Kế hoạch): trang nào thừa thì giữ lại link hợp nhất, trang nào thiếu thì thêm bài cùng chủ đề. Riêng "app vay tiền nhanh" được 193/200 vì web chỉ còn chừng ấy bài liên quan.
A12: Link "Mở rộng chủ đề" | B12: Là link thêm mới để đủ số mục tiêu (mức Cần soát). Dòng nào ghi "Liên quan rộng" thì đọc bài trước, thấy không hợp thì bỏ qua.

Sheet Kế hoạch chèn link
A1: STT | B1: Nhóm | C1: Từ khoá chính | D1: Landingpage (trang đích) | E1: Số inlink mục tiêu | F1: Tổng số link | G1: Phù hợp cao | H1: Có thể đi | I1: Cần soát | J1: Tình trạng | K1: Hoàn thiện | L1: Ghi chú | M1: {=TOROW({"Anchortext "&TEXT(SEQUENCE(200,1),"000"),"URL "&TEXT(SEQUENCE(200,1),"000")&" (bài đặt link)"})} -> Anchortext 001 | N1: URL 001 (bài đặt link) | O1: Anchortext 002 | P1: URL 002 (bài đặt link) | Q1: Anchortext 003 | R1: URL 003 (bài đặt link) | S1: Anchortext 004 | T1: URL 004 (bài đặt link) | U1: Anchortext 005 | V1: URL 005 (bài đặt link) | W1: Anchortext 006 | X1: URL 006 (bài đặt link) | Y1: Anchortext 007 | Z1: URL 007 (bài đặt link) | AA1: Anchortext 008 | AB1: URL 008 (bài đặt link) | AC1: Anchortext 009 | AD1: URL 009 (bài đặt link) | AE1: Anchortext 010 | AF1: URL 010 (bài đặt link) | AG1: Anchortext 011 | AH1: URL 011 (bài đặt link) | AI1: Anchortext 012 | AJ1: URL 012 (bài đặt link) | AK1: Anchortext 013 | AL1: URL 013 (bài đặt link) | AM1: Anchortext 014 | AN1: URL 014 (bài đặt link) | AO1: Anchortext 015 | AP1: URL 015 (bài đặt link) | AQ1: Anchortext 016 | AR1: URL 016 (bài đặt link) | AS1: Anchortext 017 | AT1: URL 017 (bài đặt link) | AU1: Anchortext 018 | AV1: URL 018 (bài đặt link) | AW1: Anchortext 019 | AX1: URL 019 (bài đặt link) | AY1: Anchortext 020 | AZ1: URL 020 (bài đặt link) | BA1: Anchortext 021 | BB1: URL 021 (bài đặt link) | BC1: Anchortext 022 | BD1: URL 022 (bài đặt link) | BE1: Anchortext 023 | BF1: URL 023 (bài đặt link) | BG1: Anchortext 024 | BH1: URL 024 (bài đặt link) | BI1: Anchortext 025 | BJ1: URL 025 (bài đặt link) | BK1: Anchortext 026 | BL1: URL 026 (bài đặt link) | BM1: Anchortext 027 | BN1: URL 027 (bài đặt link) | BO1: Anchortext 028 | BP1: URL 028 (bài đặt link) | BQ1: Anchortext 029 | BR1: URL 029 (bài đặt link) | BS1: Anchortext 030 | BT1: URL 030 (bài đặt link) | BU1: Anchortext 031 | BV1: URL 031 (bài đặt link) | BW1: Anchortext 032 | BX1: URL 032 (bài đặt link) | BY1: Anchortext 033 | BZ1: URL 033 (bài đặt link) | CA1: Anchortext 034 | CB1: URL 034 (bài đặt link) | CC1: Anchortext 035 | CD1: URL 035 (bài đặt link) | CE1: Anchortext 036 | CF1: URL 036 (bài đặt link) | CG1: Anchortext 037 | CH1: URL 037 (bài đặt link) | CI1: Anchortext 038 | CJ1: URL 038 (bài đặt link) | CK1: Anchortext 039 | CL1: URL 039 (bài đặt link) | CM1: Anchortext 040 | CN1: URL 040 (bài đặt link) | CO1: Anchortext 041 | CP1: URL 041 (bài đặt link) | CQ1: Anchortext 042 | CR1: URL 042 (bài đặt link) | CS1: Anchortext 043 | CT1: URL 043 (bài đặt link) | CU1: Anchortext 044 | CV1: URL 044 (bài đặt link) | CW1: Anchortext 045 | CX1: URL 045 (bài đặt link) | CY1: Anchortext 046 | CZ1: URL 046 (bài đặt link) | DA1: Anchortext 047 | DB1: URL 047 (bài đặt link) | DC1: Anchortext 048 | DD1: URL 048 (bài đặt link) | DE1: Anchortext 049 | DF1: URL 049 (bài đặt link) | DG1: Anchortext 050 | DH1: URL 050 (bài đặt link) | DI1: Anchortext 051 | DJ1: URL 051 (bài đặt link) | DK1: Anchortext 052 | DL1: URL 052 (bài đặt link) | DM1: Anchortext 053 | DN1: URL 053 (bài đặt link) | DO1: Anchortext 054 | DP1: URL 054 (bài đặt link) | DQ1: Anchortext 055 | DR1: URL 055 (bài đặt link) | DS1: Anchortext 056 | DT1: URL 056 (bài đặt link) | DU1: Anchortext 057 | DV1: URL 057 (bài đặt link) | DW1: Anchortext 058 | DX1: URL 058 (bài đặt link) | DY1: Anchortext 059 | DZ1: URL 059 (bài đặt link) | EA1: Anchortext 060 | EB1: URL 060 (bài đặt link) | EC1: Anchortext 061 | ED1: URL 061 (bài đặt link) | EE1: Anchortext 062 | EF1: URL 062 (bài đặt link) | EG1: Anchortext 063 | EH1: URL 063 (bài đặt link) | EI1: Anchortext 064 | EJ1: URL 064 (bài đặt link) | EK1: Anchortext 065 | EL1: URL 065 (bài đặt link) | EM1: Anchortext 066 | EN1: URL 066 (bài đặt link) | EO1: Anchortext 067 | EP1: URL 067 (bài đặt link) | EQ1: Anchortext 068 | ER1: URL 068 (bài đặt link) | ES1: Anchortext 069 | ET1: URL 069 (bài đặt link) | EU1: Anchortext 070 | EV1: URL 070 (bài đặt link) | EW1: Anchortext 071 | EX1: URL 071 (bài đặt link) | EY1: Anchortext 072 | EZ1: URL 072 (bài đặt link) | FA1: Anchortext 073 | FB1: URL 073 (bài đặt link) | FC1: Anchortext 074 | FD1: URL 074 (bài đặt link) | FE1: Anchortext 075 | FF1: URL 075 (bài đặt link) | FG1: Anchortext 076 | FH1: URL 076 (bài đặt link) | FI1: Anchortext 077 | FJ1: URL 077 (bài đặt link) | FK1: Anchortext 078 | FL1: URL 078 (bài đặt link) | FM1: Anchortext 079 | FN1: URL 079 (bài đặt link) | FO1: Anchortext 080 | FP1: URL 080 (bài đặt link) | FQ1: Anchortext 081 | FR1: URL 081 (bài đặt link) | FS1: Anchortext 082 | FT1: URL 082 (bài đặt link) | FU1: Anchortext 083 | FV1: URL 083 (bài đặt link) | FW1: Anchortext 084 | FX1: URL 084 (bài đặt link) | FY1: Anchortext 085 | FZ1: URL 085 (bài đặt link) | GA1: Anchortext 086 | GB1: URL 086 (bài đặt link) | GC1: Anchortext 087 | GD1: URL 087 (bài đặt link) | GE1: Anchortext 088 | GF1: URL 088 (bài đặt link) | GG1: Anchortext 089 | GH1: URL 089 (bài đặt link) | GI1: Anchortext 090 | GJ1: URL 090 (bài đặt link) | GK1: Anchortext 091 | GL1: URL 091 (bài đặt link) | GM1: Anchortext 092 | GN1: URL 092 (bài đặt link) | GO1: Anchortext 093 | GP1: URL 093 (bài đặt link) | GQ1: Anchortext 094 | GR1: URL 094 (bài đặt link) | GS1: Anchortext 095 | GT1: URL 095 (bài đặt link) | GU1: Anchortext 096 | GV1: URL 096 (bài đặt link) | GW1: Anchortext 097 | GX1: URL 097 (bài đặt link) | GY1: Anchortext 098 | GZ1: URL 098 (bài đặt link) | HA1: Anchortext 099 | HB1: URL 099 (bài đặt link) | HC1: Anchortext 100 | HD1: URL 100 (bài đặt link) | HE1: Anchortext 101 | HF1: URL 101 (bài đặt link) | HG1: Anchortext 102 | HH1: URL 102 (bài đặt link) | HI1: Anchortext 103 | HJ1: URL 103 (bài đặt link) | HK1: Anchortext 104 | HL1: URL 104 (bài đặt link) | HM1: Anchortext 105 | HN1: URL 105 (bài đặt link) | HO1: Anchortext 106 | HP1: URL 106 (bài đặt link) | HQ1: Anchortext 107 | HR1: URL 107 (bài đặt link) | HS1: Anchortext 108 | HT1: URL 108 (bài đặt link) | HU1: Anchortext 109 | HV1: URL 109 (bài đặt link) | HW1: Anchortext 110 | HX1: URL 110 (bài đặt link) | HY1: Anchortext 111 | HZ1: URL 111 (bài đặt link) | IA1: Anchortext 112 | IB1: URL 112 (bài đặt link) | IC1: Anchortext 113 | ID1: URL 113 (bài đặt link) | IE1: Anchortext 114 | IF1: URL 114 (bài đặt link) | IG1: Anchortext 115 | IH1: URL 115 (bài đặt link) | II1: Anchortext 116 | IJ1: URL 116 (bài đặt link) | IK1: Anchortext 117 | IL1: URL 117 (bài đặt link) | IM1: Anchortext 118 | IN1: URL 118 (bài đặt link) | IO1: Anchortext 119 | IP1: URL 119 (bài đặt link) | IQ1: Anchortext 120 | IR1: URL 120 (bài đặt link) | IS1: Anchortext 121 | IT1: URL 121 (bài đặt link) | IU1: Anchortext 122 | IV1: URL 122 (bài đặt link) | IW1: Anchortext 123 | IX1: URL 123 (bài đặt link) | IY1: Anchortext 124 | IZ1: URL 124 (bài đặt link) | JA1: Anchortext 125 | JB1: URL 125 (bài đặt link) | JC1: Anchortext 126 | JD1: URL 126 (bài đặt link) | JE1: Anchortext 127 | JF1: URL 127 (bài đặt link) | JG1: Anchortext 128 | JH1: URL 128 (bài đặt link) | JI1: Anchortext 129 | JJ1: URL 129 (bài đặt link) | JK1: Anchortext 130 | JL1: URL 130 (bài đặt link) | JM1: Anchortext 131 | JN1: URL 131 (bài đặt link) | JO1: Anchortext 132 | JP1: URL 132 (bài đặt link) | JQ1: Anchortext 133 | JR1: URL 133 (bài đặt link) | JS1: Anchortext 134 | JT1: URL 134 (bài đặt link) | JU1: Anchortext 135 | JV1: URL 135 (bài đặt link) | JW1: Anchortext 136 | JX1: URL 136 (bài đặt link) | JY1: Anchortext 137 | JZ1: URL 137 (bài đặt link) | KA1: Anchortext 138 | KB1: URL 138 (bài đặt link) | KC1: Anchortext 139 | KD1: URL 139 (bài đặt link) | KE1: Anchortext 140 | KF1: URL 140 (bài đặt link) | KG1: Anchortext 141 | KH1: URL 141 (bài đặt link) | KI1: Anchortext 142 | KJ1: URL 142 (bài đặt link) | KK1: Anchortext 143 | KL1: URL 143 (bài đặt link) | KM1: Anchortext 144 | KN1: URL 144 (bài đặt link) | KO1: Anchortext 145 | KP1: URL 145 (bài đặt link) | KQ1: Anchortext 146 | KR1: URL 146 (bài đặt link) | KS1: Anchortext 147 | KT1: URL 147 (bài đặt link) | KU1: Anchortext 148 | KV1: URL 148 (bài đặt link) | KW1: Anchortext 149 | KX1: URL 149 (bài đặt link) | KY1: Anchortext 150 | KZ1: URL 150 (bài đặt link) | LA1: Anchortext 151 | LB1: URL 151 (bài đặt link) | LC1: Anchortext 152 | LD1: URL 152 (bài đặt link) | LE1: Anchortext 153 | LF1: URL 153 (bài đặt link) | LG1: Anchortext 154 | LH1: URL 154 (bài đặt link) | LI1: Anchortext 155 | LJ1: URL 155 (bài đặt link) | LK1: Anchortext 156 | LL1: URL 156 (bài đặt link) | LM1: Anchortext 157 | LN1: URL 157 (bài đặt link) | LO1: Anchortext 158 | LP1: URL 158 (bài đặt link) | LQ1: Anchortext 159 | LR1: URL 159 (bài đặt link) | LS1: Anchortext 160 | LT1: URL 160 (bài đặt link) | LU1: Anchortext 161 | LV1: URL 161 (bài đặt link) | LW1: Anchortext 162 | LX1: URL 162 (bài đặt link) | LY1: Anchortext 163 | LZ1: URL 163 (bài đặt link) | MA1: Anchortext 164 | MB1: URL 164 (bài đặt link) | MC1: Anchortext 165 | MD1: URL 165 (bài đặt link) | ME1: Anchortext 166 | MF1: URL 166 (bài đặt link) | MG1: Anchortext 167 | MH1: URL 167 (bài đặt link) | MI1: Anchortext 168 | MJ1: URL 168 (bài đặt link) | MK1: Anchortext 169 | ML1: URL 169 (bài đặt link) | MM1: Anchortext 170 | MN1: URL 170 (bài đặt link) | MO1: Anchortext 171 | MP1: URL 171 (bài đặt link) | MQ1: Anchortext 172 | MR1: URL 172 (bài đặt link) | MS1: Anchortext 173 | MT1: URL 173 (bài đặt link) | MU1: Anchortext 174 | MV1: URL 174 (bài đặt link) | MW1: Anchortext 175 | MX1: URL 175 (bài đặt link) | MY1: Anchortext 176 | MZ1: URL 176 (bài đặt link) | NA1: Anchortext 177 | NB1: URL 177 (bài đặt link) | NC1: Anchortext 178 | ND1: URL 178 (bài đặt link) | NE1: Anchortext 179 | NF1: URL 179 (bài đặt link) | NG1: Anchortext 180 | NH1: URL 180 (bài đặt link) | NI1: Anchortext 181 | NJ1: URL 181 (bài đặt link) | NK1: Anchortext 182 | NL1: URL 182 (bài đặt link) | NM1: Anchortext 183 | NN1: URL 183 (bài đặt link) | NO1: Anchortext 184 | NP1: URL 184 (bài đặt link) | NQ1: Anchortext 185 | NR1: URL 185 (bài đặt link) | NS1: Anchortext 186 | NT1: URL 186 (bài đặt link) | NU1: Anchortext 187 | NV1: URL 187 (bài đặt link) | NW1: Anchortext 188 | NX1: URL 188 (bài đặt link) | NY1: Anchortext 189 | NZ1: URL 189 (bài đặt link) | OA1: Anchortext 190 | OB1: URL 190 (bài đặt link) | OC1: Anchortext 191 | OD1: URL 191 (bài đặt link) | OE1: Anchortext 192 | OF1: URL 192 (bài đặt link) | OG1: Anchortext 193 | OH1: URL 193 (bài đặt link) | OI1: Anchortext 194 | OJ1: URL 194 (bài đặt link) | OK1: Anchortext 195 | OL1: URL 195 (bài đặt link) | OM1: Anchortext 196 | ON1: URL 196 (bài đặt link) | OO1: Anchortext 197 | OP1: URL 197 (bài đặt link) | OQ1: Anchortext 198 | OR1: URL 198 (bài đặt link) | OS1: Anchortext 199 | OT1: URL 199 (bài đặt link) | OU1: Anchortext 200 | OV1: URL 200 (bài đặt link)
A2: 1 | B2: Auto Loan | C2: lãi suất vay mua ô tô | D2: https://techcombank.com/thong-tin/blog/lai-suat-vay-mua-o-to | E2: 30 | F2: =COUNTIF('Tổng hợp 75 trang đích'!$B$2:$B$3400,$D2) -> 30 | G2: =COUNTIFS('Tổng hợp 75 trang đích'!$B$2:$B$3400,$D2,'Tổng hợp 75 trang đích'!$K$2:$K$3400,"PHÙ HỢP CAO") -> 4 | H2: =COUNTIFS('Tổng hợp 75 trang đích'!$B$2:$B$3400,$D2,'Tổng hợp 75 trang đích'!$K$2:$K$3400,"CÓ THỂ ĐI") -> 1 | I2: =COUNTIFS('Tổng hợp 75 trang đích'!$B$2:$B$3400,$D2,'Tổng hợp 75 trang đích'!$K$2:$K$3400,"CẦN SOÁT") -> 25 | J2: Chưa hoàn thành | K2: FALSE | M2: =IFERROR(__xludf.DUMMYFUNCTION("IFERROR(TOROW(CHOOSECOLS(SORT(FILTER({'Tổng hợp 75 trang đích'!$J$2:$J$3400,'Tổng hợp 75 trang đích'!$I$2:$I$3400,MATCH('Tổng hợp 75 trang đích'!$K$2:$K$3400,{""PHÙ HỢP CAO"",""CÓ THỂ ĐI"",""CẦN SOÁT""},0)},'Tổng hợp 75 trang đích'!$B$2:$B$3400=$D2),3,TRU"&"E),1,2)),"""")"),"lãi suất vay mua ô tô") -> lãi suất vay mua ô tô | N2: =IFERROR(__xludf.DUMMYFUNCTION("""COMPUTED_VALUE"""),"https://techcombank.com/thong-tin/blog/vay-mua-xe-tra-gop-ngan-hang-nao-tot-nhat") -> https://techcombank.com/thong-tin/blog/vay-mua-xe-tra-gop-ngan-hang-nao-tot-nhat | O2: =IFERROR(__xludf.DUMMYFUNCTION("""COMPUTED_VALUE"""),"lãi suất vay mua xe ô tô") -> lãi suất vay mua xe ô tô | P2: =IFERROR(__xludf.DUMMYFUNCTION("""COMPUTED_VALUE"""),"https://techcombank.com/thong-tin/blog/co-nen-mua-o-to-tra-gop") -> https://techcombank.com/thong-tin/blog/co-nen-mua-o-to-tra-gop | Q2: =IFERROR(__xludf.DUMMYFUNCTION("""COMPUTED_VALUE"""),"lãi suất vay mua ô tô các ngân hàng") -> lãi suất vay mua ô tô các ngân hàng | R2: =IFERROR(__xludf.DUMMYFUNCTION("""COMPUTED_VALUE"""),"https://techcombank.com/thong-tin/blog/thu-tuc-mua-xe-tra-gop") -> https://techcombank.com/thong-tin/blog/thu-tuc-mua-xe-tra-gop | S2: =IFERROR(__xludf.DUMMYFUNCTION("""COMPUTED_VALUE"""),"mua xe trả góp lãi suất bao nhiêu") -> mua xe trả góp lãi suất bao nhiêu | T2: =IFERROR(__xludf.DUMMYFUNCTION("""COMPUTED_VALUE"""),"https://techcombank.com/thong-tin/blog/nen-mua-xe-tra-gop-hay-tra-thang") -> https://techcombank.com/thong-tin/blog/nen-mua-xe-tra-gop-hay-tra-thang | U2: =IFERROR(__xludf.DUMMYFUNCTION("""COMPUTED_VALUE"""),"lãi suất vay mua ô tô") -> lãi suất vay mua ô tô | V2: =IFERROR(__xludf.DUMMYFUNCTION("""COMPUTED_VALUE"""),"https://techcombank.com/thong-tin/blog/vay-the-chap-xe-o-to-cu") -> https://techcombank.com/thong-tin/blog/vay-the-chap-xe-o-to-cu | W2: =IFERROR(__xludf.DUMMYFUNCTION("""COMPUTED_VALUE"""),"lãi suất vay mua xe ô tô") -> lãi suất vay mua xe ô tô | X2: =IFERROR(__xludf.DUMMYFUNCTION("""COMPUTED_VALUE"""),"https://techcombank.com/thong-tin/blog/mua-bao-hiem-o-to-dien") -> https://techcombank.com/thong-tin/blog/mua-bao-hiem-o-to-dien | Y2: =IFERROR(__xludf.DUMMYFUNCTION("""COMPUTED_VALUE"""),"lãi suất vay mua ô tô các ngân hàng") -> lãi suất vay mua ô tô các ngân hàng | Z2: =IFERROR(__xludf.DUMMYFUNCTION("""COMPUTED_VALUE"""),"https://techcombank.com/thong-tin/blog/mua-bao-hiem-o-to") -> https://techcombank.com/thong-tin/blog/mua-bao-hiem-o-to | AA2: =IFERROR(__xludf.DUMMYFUNCTION("""COMPUTED_VALUE"""),"mua xe trả góp lãi suất bao nhiêu") -> mua xe trả góp lãi suất bao nhiêu | AB2: =IFERROR(__xludf.DUMMYFUNCTION("""COMPUTED_VALUE"""),"https://techcombank.com/thong-tin/blog/bao-hiem-vat-chat-xe-o-to") -> https://techcombank.com/thong-tin/blog/bao-hiem-vat-chat-xe-o-to | AC2: =IFERROR(__xludf.DUMMYFUNCTION("""COMPUTED_VALUE"""),"lãi suất vay mua ô tô") -> lãi suất vay mua ô tô | AD2: =IFERROR(__xludf.DUMMYFUNCTION("""COMPUTED_VALUE"""),"https://techcombank.com/thong-tin/blog/nen-mua-xe-o-to-dien-hay-xe-xang") -> https://techcombank.com/thong-tin/blog/nen-mua-xe-o-to-dien-hay-xe-xang | AE2: =IFERROR(__xludf.DUMMYFUNCTION("""COMPUTED_VALUE"""),"lãi suất vay mua xe ô tô") -> lãi suất vay mua xe ô tô | AF2: =IFERROR(__xludf.DUMMYFUNCTION("""COMPUTED_VALUE"""),"https://techcombank.com/thong-tin/blog/tin-chap-doanh-nghiep") -> https://techcombank.com/thong-tin/blog/tin-chap-doanh-nghiep | AG2: =IFERROR(__xludf.DUMMYFUNCTION("""COMPUTED_VALUE"""),"lãi suất vay mua ô tô các ngân hàng") -> lãi suất vay mua ô tô các ngân hàng | AH2: =IFERROR(__xludf.DUMMYFUNCTION("""COMPUTED_VALUE"""),"https://techcombank.com/thong-tin/blog/vay-mua-nha-o-xa-hoi") -> https://techcombank.com/thong-tin/blog/vay-mua-nha-o-xa-hoi | AI2: =IFERROR(__xludf.DUMMYFUNCTION("""COMPUTED_VALUE"""),"mua xe trả góp lãi suất bao nhiêu") -> mua xe trả góp lãi suất bao nhiêu | AJ2: =IFERROR(__xludf.DUMMYFUNCTION("""COMPUTED_VALUE"""),"https://techcombank.com/thong-tin/blog/cach-tinh-lai-vay-ngan-hang") -> https://techcombank.com/thong-tin/blog/cach-tinh-lai-vay-ngan-hang | AK2: =IFERROR(__xludf.DUMMYFUNCTION("""COMPUTED_VALUE"""),"lãi suất vay mua ô tô") -> lãi suất vay mua ô tô | AL2: =IFERROR(__xludf.DUMMYFUNCTION("""COMPUTED_VALUE"""),"https://techcombank.com/thong-tin/blog/vay-san-xuat-kinh-doanh") -> https://techcombank.com/thong-tin/blog/vay-san-xuat-kinh-doanh | AM2: =IFERROR(__xludf.DUMMYFUNCTION("""COMPUTED_VALUE"""),"lãi suất vay mua xe ô tô") -> lãi suất vay mua xe ô tô | AN2: =IFERROR(__xludf.DUMMYFUNCTION("""COMPUTED_VALUE"""),"https://techcombank.com/thong-tin/blog/lai-suat-vay-tin-chap") -> https://techcombank.com/thong-tin/blog/lai-suat-vay-tin-chap | AO2: =IFERROR(__xludf.DUMMYFUNCTION("""COMPUTED_VALUE"""),"lãi suất vay mua ô tô các ngân hàng") -> lãi suất vay mua ô tô các ngân hàng | AP2: =IFERROR(__xludf.DUMMYFUNCTION("""COMPUTED_VALUE"""),"https://techcombank.com/thong-tin/blog/cac-hinh-thuc-vay-von-ngan-hang") -> https://techcombank.com/thong-tin/blog/cac-hinh-thuc-vay-von-ngan-hang | AQ2: =IFERROR(__xludf.DUMMYFUNCTION("""COMPUTED_VALUE"""),"mua xe trả góp lãi suất bao nhiêu") -> mua xe trả góp lãi suất bao nhiêu | AR2: =IFERROR(__xludf.DUMMYFUNCTION("""COMPUTED_VALUE"""),"https://techcombank.com/thong-tin/blog/vay-tin-chap-va-vay-the-chap") -> https://techcombank.com/thong-tin/blog/vay-tin-chap-va-vay-the-chap | AS2: =IFERROR(__xludf.DUMMYFUNCTION("""COMPUTED_VALUE"""),"lãi suất vay mua ô tô") -> lãi suất vay mua ô tô | AT2: =IFERROR(__xludf.DUMMYFUNCTION("""COMPUTED_VALUE"""),"https://techcombank.com/thong-tin/blog/lai-suat-vay-the-chap-so-do") -> https://techcombank.com/thong-tin/blog/lai-suat-vay-the-chap-so-do | AU2: =IFERROR(__xludf.DUMMYFUNCTION("""COMPUTED_VALUE"""),"lãi suất vay mua xe ô tô") -> lãi suất vay mua xe ô tô | AV2: =IFERROR(__xludf.DUMMYFUNCTION("""COMPUTED_VALUE"""),"https://techcombank.com/thong-tin/blog/co-100-trieu-co-mua-nen-mua-tra-gop") -> https://techcombank.com/thong-tin/blog/co-100-trieu-co-mua-nen-mua-tra-gop | AW2: =IFERROR(__xludf.DUMMYFUNCTION("""COMPUTED_VALUE"""),"lãi suất vay mua ô tô các ngân hàng") -> lãi suất vay mua ô tô các ngân hàng | AX2: =IFERROR(__xludf.DUMMYFUNCTION("""COMPUTED_VALUE"""),"https://techcombank.com/thong-tin/blog/nen-vay-tin-chap-o-dau") -> https://techcombank.com/thong-tin/blog/nen-vay-tin-chap-o-dau | AY2: =IFERROR(__xludf.DUMMYFUNCTION("""COMPUTED_VALUE"""),"mua xe trả góp lãi suất bao nhiêu") -> mua xe trả góp lãi suất bao nhiêu | AZ2: =IFERROR(__xludf.DUMMYFUNCTION("""COMPUTED_VALUE"""),"https://techcombank.com/thong-tin/blog/vay-the-chap-so-hong") -> https://techcombank.com/thong-tin/blog/vay-the-chap-so-hong | BA2: =IFERROR(__xludf.DUMMYFUNCTION("""COMPUTED_VALUE"""),"lãi suất vay mua ô tô") -> lãi suất vay mua ô tô | BB2: =IFERROR(__xludf.DUMMYFUNCTION("""COMPUTED_VALUE"""),"https://techcombank.com/thong-tin/blog/mua-nha-tra-gop-dua-truoc-100-trieu") -> https://techcombank.com/thong-tin/blog/mua-nha-tra-gop-dua-truoc-100-trieu | BC2: =IFERROR(__xludf.DUMMYFUNCTION("""COMPUTED_VALUE"""),"lãi suất vay mua xe ô tô") -> lãi suất vay mua xe ô tô | BD2: =IFERROR(__xludf.DUMMYFUNCTION("""COMPUTED_VALUE"""),"https://techcombank.com/thong-tin/blog/vay-300-trieu") -> https://techcombank.com/thong-tin/blog/vay-300-trieu | BE2: =IFERROR(__xludf.DUMMYFUNCTION("""COMPUTED_VALUE"""),"lãi suất vay mua ô tô các ngân hàng") -> lãi suất vay mua ô tô các ngân hàng | BF2: =IFERROR(__xludf.DUMMYFUNCTION("""COMPUTED_VALUE"""),"https://techcombank.com/thong-tin/blog/vay-100-trieu") -> https://techcombank.com/thong-tin/blog/vay-100-trieu | BG2: =IFERROR(__xludf.DUMMYFUNCTION("""COMPUTED_VALUE"""),"mua xe trả góp lãi suất bao nhiêu") -> mua xe trả góp lãi suất bao nhiêu | BH2: =IFERROR(__xludf.DUMMYFUNCTION("""COMPUTED_VALUE"""),"https://techcombank.com/thong-tin/blog/vay-30-trieu") -> https://techcombank.com/thong-tin/blog/vay-30-trieu | BI2: =IFERROR(__xludf.DUMMYFUNCTION("""COMPUTED_VALUE"""),"lãi suất vay mua ô tô") -> lãi suất vay mua ô tô | BJ2: =IFERROR(__xludf.DUMMYFUNCTION("""COMPUTED_VALUE"""),"https://techcombank.com/thong-tin/blog/vay-the-chap-kinh-doanh") -> https://techcombank.com/thong-tin/blog/vay-the-chap-kinh-doanh | BK2: =IFERROR(__xludf.DUMMYFUNCTION("""COMPUTED_VALUE"""),"lãi suất vay mua xe ô tô") -> lãi suất vay mua xe ô tô | BL2: =IFERROR(__xludf.DUMMYFUNCTION("""COMPUTED_VALUE"""),"https://techcombank.com/thong-tin/blog/vay-200-trieu") -> https://techcombank.com/thong-tin/blog/vay-200-trieu | BM2: =IFERROR(__xludf.DUMMYFUNCTION("""COMPUTED_VALUE"""),"lãi suất vay mua ô tô các ngân hàng") -> lãi suất vay mua ô tô các ngân hàng | BN2: =IFERROR(__xludf.DUMMYFUNCTION("""COMPUTED_VALUE"""),"https://techcombank.com/thong-tin/blog/vay-thau-chi-bang-so-tiet-kiem") -> https://techcombank.com/thong-tin/blog/vay-thau-chi-bang-so-tiet-kiem | BO2: =IFERROR(__xludf.DUMMYFUNCTION("""COMPUTED_VALUE"""),"mua xe trả góp lãi suất bao nhiêu") -> mua xe trả góp lãi suất bao nhiêu | BP2: =IFERROR(__xludf.DUMMYFUNCTION("""COMPUTED_VALUE"""),"https://techcombank.com/thong-tin/blog/vay-tra-gop") -> https://techcombank.com/thong-tin/blog/vay-tra-gop | BQ2: =IFERROR(__xludf.DUMMYFUNCTION("""COMPUTED_VALUE"""),"lãi suất vay mua ô tô") -> lãi suất vay mua ô tô | BR2: =IFERROR(__xludf.DUMMYFUNCTION("""COMPUTED_VALUE"""),"https://techcombank.com/thong-tin/blog/lai-suat-vay-the-chap") -> https://techcombank.com/thong-tin/blog/lai-suat-vay-the-chap | BS2: =IFERROR(__xludf.DUMMYFUNCTION("""COMPUTED_VALUE"""),"lãi suất vay mua xe ô tô") -> lãi suất vay mua xe ô tô | BT2: =IFERROR(__xludf.DUMMYFUNCTION("""COMPUTED_VALUE"""),"https://techcombank.com/thong-tin/blog/lai-suat-vay-thau-chi") -> https://techcombank.com/thong-tin/blog/lai-suat-vay-thau-chi
A3: 2 | B3: Business Account | C3: nộp thuế đất qua ngân hàng | D3: https://techcombank.com/thong-tin/blog/nop-thue-dat-qua-ngan-hang | E3: 100 | F3: =COUNTIF('Tổng hợp 75 trang đích'!$B$2:$B$3400,$D3) -> 100 | G3: =COUNTIFS('Tổng hợp 75 trang đích'!$B$2:$B$3400,$D3,'Tổng hợp 75 trang đích'!$K$2:$K$3400,"PHÙ HỢP CAO") -> 1 | H3: =COUNTIFS('Tổng hợp 75 trang đích'!$B$2:$B$3400,$D3,'Tổng hợp 75 trang đích'!$K$2:$K$3400,"CÓ THỂ ĐI") -> 2 | I3: =COUNTIFS('Tổng hợp 75 trang đích'!$B$2:$B$3400,$D3,'Tổng hợp 75 trang đích'!$K$2:$K$3400,"CẦN SOÁT") -> 97 | J3: Chưa hoàn thành | K3: FALSE | M3: =IFERROR(__xludf.DUMMYFUNCTION("IFERROR(TOROW(CHOOSECOLS(SORT(FILTER({'Tổng hợp 75 trang đích'!$J$2:$J$3400,'Tổng hợp 75 trang đích'!$I$2:$I$3400,MATCH('Tổng hợp 75 trang đích'!$K$2:$K$3400,{""PHÙ HỢP CAO"",""CÓ THỂ ĐI"",""CẦN SOÁT""},0)},'Tổng hợp 75 trang đích'!$B$2:$B$3400=$D3),3,TRU"&"E),1,2)),"""")"),"đóng thuế đất online") -> đóng thuế đất online | N3: =IFERROR(__xludf.DUMMYFUNCTION("""COMPUTED_VALUE"""),"https://techcombank.com/thong-tin/blog/lien-ket-tai-khoan-ngan-hang-voi-etax-mobile") -> https://techcombank.com/thong-tin/blog/lien-ket-tai-khoan-ngan-hang-voi-etax-mobile | O3: =IFERROR(__xludf.DUMMYFUNCTION("""COMPUTED_VALUE"""),"nộp thuế đất online") -> nộp thuế đất online | P3: =IFERROR(__xludf.DUMMYFUNCTION("""COMPUTED_VALUE"""),"https://techcombank.com/thong-tin/blog/cach-nop-thue-dien-tu") -> https://techcombank.com/thong-tin/blog/cach-nop-thue-dien-tu | Q3: =IFERROR(__xludf.DUMMYFUNCTION("""COMPUTED_VALUE"""),"cách nộp thuế đất online") -> cách nộp thuế đất online | R3: =IFERROR(__xludf.DUMMYFUNCTION("""COMPUTED_VALUE"""),"https://techcombank.com/thong-tin/blog/ho-so-thu-tuc-xoa-the-chap") -> https://techcombank.com/thong-tin/blog/ho-so-thu-tuc-xoa-the-chap | S3: =IFERROR(__xludf.DUMMYFUNCTION("""COMPUTED_VALUE"""),"đóng thuế đất online") -> đóng thuế đất online | T3: =IFERROR(__xludf.DUMMYFUNCTION("""COMPUTED_VALUE"""),"https://techcombank.com/thong-tin/blog/quyet-toan-thue-thu-nhap-ca-nhan") -> https://techcombank.com/thong-tin/blog/quyet-toan-thue-thu-nhap-ca-nhan | U3: =IFERROR(__xludf.DUMMYFUNCTION("""COMPUTED_VALUE"""),"nộp thuế đất online") -> nộp thuế đất online | V3: =IFERROR(__xludf.DUMMYFUNCTION("""COMPUTED_VALUE"""),"https://techcombank.com/thong-tin/blog/tra-cuu-no-thue-hai-quan") -> https://techcombank.com/thong-tin/blog/tra-cuu-no-thue-hai-quan | W3: =IFERROR(__xludf.DUMMYFUNCTION("""COMPUTED_VALUE"""),"cách nộp thuế đất online") -> cách nộp thuế đất online | X3: =IFERROR(__xludf.DUMMYFUNCTION("""COMPUTED_VALUE"""),"https://techcombank.com/thong-tin/blog/tra-cuu-no-thue-ho-kinh-doanh") -> https://techcombank.com/thong-tin/blog/tra-cuu-no-thue-ho-kinh-doanh | Y3: =IFERROR(__xludf.DUMMYFUNCTION("""COMPUTED_VALUE"""),"đóng thuế đất online") -> đóng thuế đất online | Z3: =IFERROR(__xludf.DUMMYFUNCTION("""COMPUTED_VALUE"""),"https://techcombank.com/thong-tin/blog/truy-thu-thue-ho-kinh-doanh") -> https://techcombank.com/thong-tin/blog/truy-thu-thue-ho-kinh-doanh | AA3: =IFERROR(__xludf.DUMMYFUNCTION("""COMPUTED_VALUE"""),"nộp thuế đất online") -> nộp thuế đất online | AB3: =IFERROR(__xludf.DUMMYFUNCTION("""COMPUTED_VALUE"""),"https://techcombank.com/thong-tin/blog/kiem-tra-thue-ho-kinh-doanh") -> https://techcombank.com/thong-tin/blog/kiem-tra-thue-ho-kinh-doanh | AC3: =IFERROR(__xludf.DUMMYFUNCTION("""COMPUTED_VALUE"""),"cách nộp thuế đất online") -> cách nộp thuế đất online | AD3: =IFERROR(__xludf.DUMMYFUNCTION("""COMPUTED_VALUE"""),"https://techcombank.com/thong-tin/blog/tra-cuu-no-thue-ca-nhan") -> https://techcombank.com/thong-tin/blog/tra-cuu-no-thue-ca-nhan | AE3: =IFERROR(__xludf.DUMMYFUNCTION("""COMPUTED_VALUE"""),"đóng thuế đất online") -> đóng thuế đất online | AF3: =IFERROR(__xludf.DUMMYFUNCTION("""COMPUTED_VALUE"""),"https://techcombank.com/thong-tin/blog/hoan-thue-thu-nhap-ca-nhan") -> https://techcombank.com/thong-tin/blog/hoan-thue-thu-nhap-ca-nhan | AG3: =IFERROR(__xludf.DUMMYFUNCTION("""COMPUTED_VALUE"""),"nộp thuế đất online") -> nộp thuế đất online | AH3: =IFERROR(__xludf.DUMMYFUNCTION("""COMPUTED_VALUE"""),"https://techcombank.com/thong-tin/blog/ke-khai-thue-ho-kinh-doanh-ca-the-online") -> https://techcombank.com/thong-tin/blog/ke-khai-thue-ho-kinh-doanh-ca-the-online | AI3: =IFERROR(__xludf.DUMMYFUNCTION("""COMPUTED_VALUE"""),"cách nộp thuế đất online") -> cách nộp thuế đất online | AJ3: =IFERROR(__xludf.DUMMYFUNCTION("""COMPUTED_VALUE"""),"https://techcombank.com/thong-tin/blog/thue-thuong-mai-dien-tu") -> https://techcombank.com/thong-tin/blog/thue-thuong-mai-dien-tu | AK3: =IFERROR(__xludf.DUMMYFUNCTION("""COMPUTED_VALUE"""),"đóng thuế đất online") -> đóng thuế đất online | AL3: =IFERROR(__xludf.DUMMYFUNCTION("""COMPUTED_VALUE"""),"https://techcombank.com/thong-tin/blog/thue-thu-nhap-doanh-nghiep") -> https://techcombank.com/thong-tin/blog/thue-thu-nhap-doanh-nghiep | AM3: =IFERROR(__xludf.DUMMYFUNCTION("""COMPUTED_VALUE"""),"nộp thuế đất online") -> nộp thuế đất online | AN3: =IFERROR(__xludf.DUMMYFUNCTION("""COMPUTED_VALUE"""),"https://techcombank.com/thong-tin/blog/ke-khai-thue-doanh-nghiep") -> https://techcombank.com/thong-tin/blog/ke-khai-thue-doanh-nghiep | AO3: =IFERROR(__xludf.DUMMYFUNCTION("""COMPUTED_VALUE"""),"cách nộp thuế đất online") -> cách nộp thuế đất online | AP3: =IFERROR(__xludf.DUMMYFUNCTION("""COMPUTED_VALUE"""),"https://techcombank.com/thong-tin/blog/tra-cuu-no-thue-doanh-nghiep") -> https://techcombank.com/thong-tin/blog/tra-cuu-no-thue-doanh-nghiep | AQ3: =IFERROR(__xludf.DUMMYFUNCTION("""COMPUTED_VALUE"""),"đóng thuế đất online") -> đóng thuế đất online | AR3: =IFERROR(__xludf.DUMMYFUNCTION("""COMPUTED_VALUE"""),"https://techcombank.com/thong-tin/blog/nop-thue-hai-quan") -> https://techcombank.com/thong-tin/blog/nop-thue-hai-quan | AS3: =IFERROR(__xludf.DUMMYFUNCTION("""COMPUTED_VALUE"""),"nộp thuế đất online") -> nộp thuế đất online | AT3: =IFERROR(__xludf.DUMMYFUNCTION("""COMPUTED_VALUE"""),"https://techcombank.com/thong-tin/blog/tien-chuyen-vao-tai-khoan-co-bi-tinh-thue-khong") -> https://techcombank.com/thong-tin/blog/tien-chuyen-vao-tai-khoan-co-bi-tinh-thue-khong | AU3: =IFERROR(__xludf.DUMMYFUNCTION("""COMPUTED_VALUE"""),"cách nộp thuế đất online") -> cách nộp thuế đất online | AV3: =IFERROR(__xludf.DUMMYFUNCTION("""COMPUTED_VALUE"""),"https://techcombank.com/thong-tin/blog/cach-tinh-thue-thu-nhap-ca-nhan-2025") -> https://techcombank.com/thong-tin/blog/cach-tinh-thue-thu-nhap-ca-nhan-2025 | AW3: =IFERROR(__xludf.DUMMYFUNCTION("""COMPUTED_VALUE"""),"đóng thuế đất online") -> đóng thuế đất online | AX3: =IFERROR(__xludf.DUMMYFUNCTION("""COMPUTED_VALUE"""),"https://techcombank.com/thong-tin/blog/kiem-tra-thue-thu-nhap-ca-nhan") -> https://techcombank.com/thong-tin/blog/kiem-tra-thue-thu-nhap-ca-nhan | AY3: =IFERROR(__xludf.DUMMYFUNCTION("""COMPUTED_VALUE"""),"nộp thuế đất online") -> nộp thuế đất online | AZ3: =IFERROR(__xludf.DUMMYFUNCTION("""COMPUTED_VALUE"""),"https://techcombank.com/thong-tin/blog/lai-suat-vay-the-chap-so-do") -> https://techcombank.com/thong-tin/blog/lai-suat-vay-the-chap-so-do | BA3: =IFERROR(__xludf.DUMMYFUNCTION("""COMPUTED_VALUE"""),"cách nộp thuế đất online") -> cách nộp thuế đất online | BB3: =IFERROR(__xludf.DUMMYFUNCTION("""COMPUTED_VALUE"""),"https://techcombank.com/thong-tin/blog/han-muc-vay-the-chap-so-do") -> https://techcombank.com/thong-tin/blog/han-muc-vay-the-chap-so-do | BC3: =IFERROR(__xludf.DUMMYFUNCTION("""COMPUTED_VALUE"""),"đóng thuế đất online") -> đóng thuế đất online | BD3: =IFERROR(__xludf.DUMMYFUNCTION("""COMPUTED_VALUE"""),"https://techcombank.com/thong-tin/blog/thue-thu-nhap-ca-nhan") -> https://techcombank.com/thong-tin/blog/thue-thu-nhap-ca-nhan | BE3: =IFERROR(__xludf.DUMMYFUNCTION("""COMPUTED_VALUE"""),"nộp thuế đất online") -> nộp thuế đất online | BF3: =IFERROR(__xludf.DUMMYFUNCTION("""COMPUTED_VALUE"""),"https://techcombank.com/thong-tin/blog/tim-hieu-ve-chinh-sach-thue-moi") -> https://techcombank.com/thong-tin/blog/tim-hieu-ve-chinh-sach-thue-moi | BG3: =IFERROR(__xludf.DUMMYFUNCTION("""COMPUTED_VALUE"""),"cách nộp thuế đất online") -> cách nộp thuế đất online | BH3: =IFERROR(__xludf.DUMMYFUNCTION("""COMPUTED_VALUE"""),"https://techcombank.com/thong-tin/blog/chuyen-doi-ho-kinh-doanh-len-doanh-nghiep") -> https://techcombank.com/thong-tin/blog/chuyen-doi-ho-kinh-doanh-len-doanh-nghiep | BI3: =IFERROR(__xludf.DUMMYFUNCTION("""COMPUTED_VALUE"""),"đóng thuế đất online") -> đóng thuế đất online | BJ3: =IFERROR(__xludf.DUMMYFUNCTION("""COMPUTED_VALUE"""),"https://techcombank.com/thong-tin/blog/nen-thanh-lap-ho-kinh-doanh-ke-khai-hay-doanh-nghiep") -> https://techcombank.com/thong-tin/blog/nen-thanh-lap-ho-kinh-doanh-ke-khai-hay-doanh-nghiep | BK3: =IFERROR(__xludf.DUMMYFUNCTION("""COMPUTED_VALUE"""),"nộp thuế đất online") -> nộp thuế đất online | BL3: =IFERROR(__xludf.DUMMYFUNCTION("""COMPUTED_VALUE"""),"https://techcombank.com/thong-tin/blog/giai-dap-ve-thue-doanh-nghiep") -> https://techcombank.com/thong-tin/blog/giai-dap-ve-thue-doanh-nghiep | BM3: =IFERROR(__xludf.DUMMYFUNCTION("""COMPUTED_VALUE"""),"cách nộp thuế đất online") -> cách nộp thuế đất online | BN3: =IFERROR(__xludf.DUMMYFUNCTION("""COMPUTED_VALUE"""),"https://techcombank.com/thong-tin/blog/dong-ma-so-thue-ho-kinh-doanh") -> https://techcombank.com/thong-tin/blog/dong-ma-so-thue-ho-kinh-doanh | BO3: =IFERROR(__xludf.DUMMYFUNCTION("""COMPUTED_VALUE"""),"đóng thuế đất online") -> đóng thuế đất online | BP3: =IFERROR(__xludf.DUMMYFUNCTION("""COMPUTED_VALUE"""),"https://techcombank.com/thong-tin/blog/khach-hang-vip-bat-dong-san") -> https://techcombank.com/thong-tin/blog/khach-hang-vip-bat-dong-san | BQ3: =IFERROR(__xludf.DUMMYFUNCTION("""COMPUTED_VALUE"""),"nộp thuế đất online") -> nộp thuế đất online | BR3: =IFERROR(__xludf.DUMMYFUNCTION("""COMPUTED_VALUE"""),"https://techcombank.com/thong-tin/blog/cach-dau-tu") -> https://techcombank.com/thong-tin/blog/cach-dau-tu | BS3: =IFERROR(__xludf.DUMMYFUNCTION("""COMPUTED_VALUE"""),"cách nộp thuế đất online") -> cách nộp thuế đất online | BT3: =IFERROR(__xludf.DUMMYFUNCTION("""COMPUTED_VALUE"""),"https://techcombank.com/thong-tin/blog/eco-card") -> https://techcombank.com/thong-tin/blog/eco-card | BU3: =IFERROR(__xludf.DUMMYFUNCTION("""COMPUTED_VALUE"""),"đóng thuế đất online") -> đóng thuế đất online | BV3: =IFERROR(__xludf.DUMMYFUNCTION("""COMPUTED_VALUE"""),"https://techcombank.com/thong-tin/blog/chuyen-gia-du-doan-gia-bat-dong-san-2025-va-cac-no-luc-tu-ngan-hang") -> https://techcombank.com/thong-tin/blog/chuyen-gia-du-doan-gia-bat-dong-san-2025-va-cac-no-luc-tu-ngan-hang | BW3: =IFERROR(__xludf.DUMMYFUNCTION("""COMPUTED_VALUE"""),"nộp thuế đất online") -> nộp thuế đất online | BX3: =IFERROR(__xludf.DUMMYFUNCTION("""COMPUTED_VALUE"""),"https://techcombank.com/thong-tin/blog/thue-phi-co-dinh-khi-chuyen-doi-tu-ho-kinh-doanh-len-doanh-nghiep") -> https://techcombank.com/thong-tin/blog/thue-phi-co-dinh-khi-chuyen-doi-tu-ho-kinh-doanh-len-doanh-nghiep | BY3: =IFERROR(__xludf.DUMMYFUNCTION("""COMPUTED_VALUE"""),"cách nộp thuế đất online") -> cách nộp thuế đất online | BZ3: =IFERROR(__xludf.DUMMYFUNCTION("""COMPUTED_VALUE"""),"https://techcombank.com/thong-tin/blog/ho-kinh-doanh-ca-the") -> https://techcombank.com/thong-tin/blog/ho-kinh-doanh-ca-the | CA3: =IFERROR(__xludf.DUMMYFUNCTION("""COMPUTED_VALUE"""),"đóng thuế đất online") -> đóng thuế đất online | CB3: =IFERROR(__xludf.DUMMYFUNCTION("""COMPUTED_VALUE"""),"https://techcombank.com/thong-tin/blog/nhung-chi-phi-khong-duoc-tru-khi-tinh-thue-tndn") -> https://techcombank.com/thong-tin/blog/nhung-chi-phi-khong-duoc-tru-khi-tinh-thue-tndn | CC3: =IFERROR(__xludf.DUMMYFUNCTION("""COMPUTED_VALUE"""),"nộp thuế đất online") -> nộp thuế đất online | CD3: =IFERROR(__xludf.DUMMYFUNCTION("""COMPUTED_VALUE"""),"https://techcombank.com/thong-tin/blog/hoa-don-dien-tu") -> https://techcombank.com/thong-tin/blog/hoa-don-dien-tu | CE3: =IFERROR(__xludf.DUMMYFUNCTION("""COMPUTED_VALUE"""),"cách nộp thuế đất online") -> cách nộp thuế đất online | CF3: =IFERROR(__xludf.DUMMYFUNCTION("""COMPUTED_VALUE"""),"https://techcombank.com/thong-tin/blog/one-stop-shop") -> https://techcombank.com/thong-tin/blog/one-stop-shop | CG3: =IFERROR(__xludf.DUMMYFUNCTION("""COMPUTED_VALUE"""),"đóng thuế đất online") -> đóng thuế đất online | CH3: =IFERROR(__xludf.DUMMYFUNCTION("""COMPUTED_VALUE"""),"https://techcombank.com/thong-tin/blog/cac-sai-lam-pho-bien-khi-chuyen-doi-ho-kinh-doanh-len-sme") -> https://techcombank.com/thong-tin/blog/cac-sai-lam-pho-bien-khi-chuyen-doi-ho-kinh-doanh-len-sme | CI3: =IFERROR(__xludf.DUMMYFUNCTION("""COMPUTED_VALUE"""),"nộp thuế đất online") -> nộp thuế đất online | CJ3: =IFERROR(__xludf.DUMMYFUNCTION("""COMPUTED_VALUE"""),"https://techcombank.com/thong-tin/blog/cach-dang-ky-ma-so-thue-ho-kinh-doanh-online") -> https://techcombank.com/thong-tin/blog/cach-dang-ky-ma-so-thue-ho-kinh-doanh-online | CK3: =IFERROR(__xludf.DUMMYFUNCTION("""COMPUTED_VALUE"""),"cách nộp thuế đất online") -> cách nộp thuế đất online | CL3: =IFERROR(__xludf.DUMMYFUNCTION("""COMPUTED_VALUE"""),"https://techcombank.com/thong-tin/blog/kiem-tra-ma-so-thue-doanh-nghiep") -> https://techcombank.com/thong-tin/blog/kiem-tra-ma-so-thue-doanh-nghiep | CM3: =IFERROR(__xludf.DUMMYFUNCTION("""COMPUTED_VALUE"""),"đóng thuế đất online") -> đóng thuế đất online | CN3: =IFERROR(__xludf.DUMMYFUNCTION("""COMPUTED_VALUE"""),"https://techcombank.com/thong-tin/blog/tra-cuu-ma-so-thue-ho-kinh-doanh") -> https://techcombank.com/thong-tin/blog/tra-cuu-ma-so-thue-ho-kinh-doanh | CO3: =IFERROR(__xludf.DUMMYFUNCTION("""COMPUTED_VALUE"""),"nộp thuế đất online") -> nộp thuế đất online | CP3: =IFERROR(__xludf.DUMMYFUNCTION("""COMPUTED_VALUE"""),"https://techcombank.com/thong-tin/blog/quyet-toan-thue-doanh-nghiep") -> https://techcombank.com/thong-tin/blog/quyet-toan-thue-doanh-nghiep | CQ3: =IFERROR(__xludf.DUMMYFUNCTION("""COMPUTED_VALUE"""),"cách nộp thuế đất online") -> cách nộp thuế đất online | CR3: =IFERROR(__xludf.DUMMYFUNCTION("""COMPUTED_VALUE"""),"https://techcombank.com/thong-tin/blog/ho-kinh-doanh-dong-thue-nhu-nao") -> https://techcombank.com/thong-tin/blog/ho-kinh-doanh-dong-thue-nhu-nao | CS3: =IFERROR(__xludf.DUMMYFUNCTION("""COMPUTED_VALUE"""),"đóng thuế đất online") -> đóng thuế đất online | CT3: =IFERROR(__xludf.DUMMYFUNCTION("""COMPUTED_VALUE"""),"https://techcombank.com/thong-tin/blog/hoan-thue-doanh-nghiep") -> https://techcombank.com/thong-tin/blog/hoan-thue-doanh-nghiep | CU3: =IFERROR(__xludf.DUMMYFUNCTION("""COMPUTED_VALUE"""),"nộp thuế đất online") -> nộp thuế đất online | CV3: =IFERROR(__xludf.DUMMYFUNCTION("""COMPUTED_VALUE"""),"https://techcombank.com/thong-tin/blog/cong-ty-su-dung-tai-khoan-ca-nhan") -> https://techcombank.com/thong-tin/blog/cong-ty-su-dung-tai-khoan-ca-nhan | CW3: =IFERROR(__xludf.DUMMYFUNCTION("""COMPUTED_VALUE"""),"cách nộp thuế đất online") -> cách nộp thuế đất online | CX3: =IFERROR(__xludf.DUMMYFUNCTION("""COMPUTED_VALUE"""),"https://techcombank.com/thong-tin/blog/kinh-nghiem-chuyen-doi-tu-ho-kinh-doanh-len-doanh-nghiep") -> https://techcombank.com/thong-tin/blog/kinh-nghiem-chuyen-doi-tu-ho-kinh-doanh-len-doanh-nghiep | CY3: =IFERROR(__xludf.DUMMYFUNCTION("""COMPUTED_VALUE"""),"đóng thuế đất online") -> đóng thuế đất online | CZ3: =IFERROR(__xludf.DUMMYFUNCTION("""COMPUTED_VALUE"""),"https://techcombank.com/thong-tin/blog/top-phan-mem-ban-hang") -> https://techcombank.com/thong-tin/blog/top-phan-mem-ban-hang | DA3: =IFERROR(__xludf.DUMMYFUNCTION("""COMPUTED_VALUE"""),"nộp thuế đất online") -> nộp thuế đất online | DB3: =IFERROR(__xludf.DUMMYFUNCTION("""COMPUTED_VALUE"""),"https://techcombank.com/thong-tin/blog/dieu-kien-thanh-lap-doanh-nghiep") -> https://techcombank.com/thong-tin/blog/dieu-kien-thanh-lap-doanh-nghiep | DC3: =IFERROR(__xludf.DUMMYFUNCTION("""COMPUTED_VALUE"""),"cách nộp thuế đất online") -> cách nộp thuế đất online | DD3: =IFERROR(__xludf.DUMMYFUNCTION("""COMPUTED_VALUE"""),"https://techcombank.com/thong-tin/blog/dang-ky-thue-ho-kinh-doanh-ca-the-online") -> https://techcombank.com/thong-tin/blog/dang-ky-thue-ho-kinh-doanh-ca-the-online | DE3: =IFERROR(__xludf.DUMMYFUNCTION("""COMPUTED_VALUE"""),"đóng thuế đất online") -> đóng thuế đất online | DF3: =IFERROR(__xludf.DUMMYFUNCTION("""COMPUTED_VALUE"""),"https://techcombank.com/thong-tin/blog/luat-thuong-mai-dien-tu") -> https://techcombank.com/thong-tin/blog/luat-thuong-mai-dien-tu | DG3: =IFERROR(__xludf.DUMMYFUNCTION("""COMPUTED_VALUE"""),"nộp thuế đất online") -> nộp thuế đất online | DH3: =IFERROR(__xludf.DUMMYFUNCTION("""COMPUTED_VALUE"""),"https://techcombank.com/thong-tin/blog/ho-so-dang-ky-thanh-lap-doanh-nghiep") -> https://techcombank.com/thong-tin/blog/ho-so-dang-ky-thanh-lap-doanh-nghiep | DI3: =IFERROR(__xludf.DUMMYFUNCTION("""COMPUTED_VALUE"""),"cách nộp thuế đất online") -> cách nộp thuế đất online | DJ3: =IFERROR(__xludf.DUMMYFUNCTION("""COMPUTED_VALUE"""),"https://techcombank.com/thong-tin/blog/thue-khoan-ho-kinh-doanh-la-gi") -> https://techcombank.com/thong-tin/blog/thue-khoan-ho-kinh-doanh-la-gi | DK3: =IFERROR(__xludf.DUMMYFUNCTION("""COMPUTED_VALUE"""),"đóng thuế đất online") -> đóng thuế đất online | DL3: =IFERROR(__xludf.DUMMYFUNCTION("""COMPUTED_VALUE"""),"https://techcombank.com/thong-tin/blog/doanh-nghiep-moi-thanh-lap-duoc-uu-dai-gi") -> https://techcombank.com/thong-tin/blog/doanh-nghiep-moi-thanh-lap-duoc-uu-dai-gi | DM3: =IFERROR(__xludf.DUMMYFUNCTION("""COMPUTED_VALUE"""),"nộp thuế đất online") -> nộp thuế đất online | DN3: =IFERROR(__xludf.DUMMYFUNCTION("""COMPUTED_VALUE"""),"https://techcombank.com/thong-tin/blog/phat-cham-dang-ky-thue-ho-kinh-doanh") -> https://techcombank.com/thong-tin/blog/phat-cham-dang-ky-thue-ho-kinh-doanh | DO3: =IFERROR(__xludf.DUMMYFUNCTION("""COMPUTED_VALUE"""),"cách nộp thuế đất online") -> cách nộp thuế đất online | DP3: =IFERROR(__xludf.DUMMYFUNCTION("""COMPUTED_VALUE"""),"https://techcombank.com/thong-tin/blog/thu-tuc-thanh-lap-doanh-nghiep") -> https://techcombank.com/thong-tin/blog/thu-tuc-thanh-lap-doanh-nghiep | DQ3: =IFERROR(__xludf.DUMMYFUNCTION("""COMPUTED_VALUE"""),"đóng thuế đất online") -> đóng thuế đất online | DR3: =IFERROR(__xludf.DUMMYFUNCTION("""COMPUTED_VALUE"""),"https://techcombank.com/thong-tin/blog/chi-phi-mo-tai-khoan-ngan-hang-cho-cong-ty") -> https://techcombank.com/thong-tin/blog/chi-phi-mo-tai-khoan-ngan-hang-cho-cong-ty | DS3: =IFERROR(__xludf.DUMMYFUNCTION("""COMPUTED_VALUE"""),"nộp thuế đất online") -> nộp thuế đất online | DT3: =IFERROR(__xludf.DUMMYFUNCTION("""COMPUTED_VALUE"""),"https://techcombank.com/thong-tin/blog/thue-doanh-nghiep-2025") -> https://techcombank.com/thong-tin/blog/thue-doanh-nghiep-2025 | DU3: =IFERROR(__xludf.DUMMYFUNCTION("""COMPUTED_VALUE"""),"cách nộp thuế đất online") -> cách nộp thuế đất online | DV3: =IFERROR(__xludf.DUMMYFUNCTION("""COMPUTED_VALUE"""),"https://techcombank.com/thong-tin/blog/khoi-nghiep-truoc-chinh-sach-thue-moi") -> https://techcombank.com/thong-tin/blog/khoi-nghiep-truoc-chinh-sach-thue-moi | DW3: =IFERROR(__xludf.DUMMYFUNCTION("""COMPUTED_VALUE"""),"đóng thuế đất online") -> đóng thuế đất online | DX3: =IFERROR(__xludf.DUMMYFUNCTION("""COMPUTED_VALUE"""),"https://techcombank.com/thong-tin/blog/dong-tai-khoan-ngan-hang-cong-ty") -> https://techcombank.com/thong-tin/blog/dong-tai-khoan-ngan-hang-cong-ty | DY3: =IFERROR(__xludf.DUMMYFUNCTION("""COMPUTED_VALUE"""),"nộp thuế đất online") -> nộp thuế đất online | DZ3: =IFERROR(__xludf.DUMMYFUNCTION("""COMPUTED_VALUE"""),"https://techcombank.com/thong-tin/blog/luu-y-khi-chuyen-tien-vao-tai-khoan-cong-ty") -> https://techcombank.com/thong-tin/blog/luu-y-khi-chuyen-tien-vao-tai-khoan-cong-ty | EA3: =IFERROR(__xludf.DUMMYFUNCTION("""COMPUTED_VALUE"""),"cách nộp thuế đất online") -> cách nộp thuế đất online | EB3: =IFERROR(__xludf.DUMMYFUNCTION("""COMPUTED_VALUE"""),"https://techcombank.com/thong-tin/blog/hieu-hiet-ve-tuan-thu-thue-cho-cac-doanh-nghiep-khoi-nghiep") -> https://techcombank.com/thong-tin/blog/hieu-hiet-ve-tuan-thu-thue-cho-cac-doanh-nghiep-khoi-nghiep | EC3: =IFERROR(__xludf.DUMMYFUNCTION("""COMPUTED_VALUE"""),"đóng thuế đất online") -> đóng thuế đất online | ED3: =IFERROR(__xludf.DUMMYFUNCTION("""COMPUTED_VALUE"""),"https://techcombank.com/thong-tin/blog/khai-bao-tai-khoan-ngan-hang-voi-co-quan-thue") -> https://techcombank.com/thong-tin/blog/khai-bao-tai-khoan-ngan-hang-voi-co-quan-thue | EE3: =IFERROR(__xludf.DUMMYFUNCTION("""COMPUTED_VALUE"""),"nộp thuế đất online") -> nộp thuế đất online | EF3: =IFERROR(__xludf.DUMMYFUNCTION("""COMPUTED_VALUE"""),"https://techcombank.com/thong-tin/blog/hoa-don-dien-tu-ho-kinh-doanh") -> https://techcombank.com/thong-tin/blog/hoa-don-dien-tu-ho-kinh-doanh | EG3: =IFERROR(__xludf.DUMMYFUNCTION("""COMPUTED_VALUE"""),"cách nộp thuế đất online") -> cách nộp thuế đất online | EH3: =IFERROR(__xludf.DUMMYFUNCTION("""COMPUTED_VALUE"""),"https://techcombank.com/thong-tin/blog/may-tinh-tien") -> https://techcombank.com/thong-tin/blog/may-tinh-tien | EI3: =IFERROR(__xludf.DUMMYFUNCTION("""COMPUTED_VALUE"""),"đóng thuế đất online") -> đóng thuế đất online | EJ3: =IFERROR(__xludf.DUMMYFUNCTION("""COMPUTED_VALUE"""),"https://techcombank.com/thong-tin/blog/phan-mem-xuat-hoa-don-dien-tu") -> https://techcombank.com/thong-tin/blog/phan-mem-xuat-hoa-don-dien-tu | EK3: =IFERROR(__xludf.DUMMYFUNCTION("""COMPUTED_VALUE"""),"nộp thuế đất online") -> nộp thuế đất online | EL3: =IFERROR(__xludf.DUMMYFUNCTION("""COMPUTED_VALUE"""),"https://techcombank.com/thong-tin/blog/nop-tien-mat-vao-tai-khoan-cong-ty") -> https://techcombank.com/thong-tin/blog/nop-tien-mat-vao-tai-khoan-cong-ty | EM3: =IFERROR(__xludf.DUMMYFUNCTION("""COMPUTED_VALUE"""),"cách nộp thuế đất online") -> cách nộp thuế đất online | EN3: =IFERROR(__xludf.DUMMYFUNCTION("""COMPUTED_VALUE"""),"https://techcombank.com/thong-tin/blog/ho-kinh-doanh-la-gi") -> https://techcombank.com/thong-tin/blog/ho-kinh-doanh-la-gi | EO3: =IFERROR(__xludf.DUMMYFUNCTION("""COMPUTED_VALUE"""),"đóng thuế đất online") -> đóng thuế đất online | EP3: =IFERROR(__xludf.DUMMYFUNCTION("""COMPUTED_VALUE"""),"https://techcombank.com/thong-tin/blog/thanh-lap-ho-kinh-doanh-ca-the") -> https://techcombank.com/thong-tin/blog/thanh-lap-ho-kinh-doanh-ca-the | EQ3: =IFERROR(__xludf.DUMMYFUNCTION("""COMPUTED_VALUE"""),"nộp thuế đất online") -> nộp thuế đất online | ER3: =IFERROR(__xludf.DUMMYFUNCTION("""COMPUTED_VALUE"""),"https://techcombank.com/thong-tin/blog/thue-ho-kinh-doanh-2025") -> https://techcombank.com/thong-tin/blog/thue-ho-kinh-doanh-2025 | ES3: =IFERROR(__xludf.DUMMYFUNCTION("""COMPUTED_VALUE"""),"cách nộp thuế đất online") -> cách nộp thuế đất online | ET3: =IFERROR(__xludf.DUMMYFUNCTION("""COMPUTED_VALUE"""),"https://techcombank.com/thong-tin/blog/mo-tai-khoan-doanh-nghiep") -> https://techcombank.com/thong-tin/blog/mo-tai-khoan-doanh-nghiep | EU3: =IFERROR(__xludf.DUMMYFUNCTION("""COMPUTED_VALUE"""),"đóng thuế đất online") -> đóng thuế đất online | EV3: =IFERROR(__xludf.DUMMYFUNCTION("""COMPUTED_VALUE"""),"https://techcombank.com/thong-tin/blog/loi-ich-khi-ho-kinh-doanh-chuyen-len-doanh-nghiep") -> https://techcombank.com/thong-tin/blog/loi-ich-khi-ho-kinh-doanh-chuyen-len-doanh-nghiep | EW3: =IFERROR(__xludf.DUMMYFUNCTION("""COMPUTED_VALUE"""),"nộp thuế đất online") -> nộp thuế đất online | EX3: =IFERROR(__xludf.DUMMYFUNCTION("""COMPUTED_VALUE"""),"https://techcombank.com/thong-tin/blog/tiem-nang-chuyen-doi-tu-ho-kinh-doanh-len-doanh-nghiep-sme") -> https://techcombank.com/thong-tin/blog/tiem-nang-chuyen-doi-tu-ho-kinh-doanh-len-doanh-nghiep-sme | EY3: =IFERROR(__xludf.DUMMYFUNCTION("""COMPUTED_VALUE"""),"cách nộp thuế đất online") -> cách nộp thuế đất online | EZ3: =IFERROR(__xludf.DUMMYFUNCTION("""COMPUTED_VALUE"""),"https://techcombank.com/thong-tin/blog/cach-tra-cuu-hoa-don-dien-tu") -> https://techcombank.com/thong-tin/blog/cach-tra-cuu-hoa-don-dien-tu | FA3: =IFERROR(__xludf.DUMMYFUNCTION("""COMPUTED_VALUE"""),"đóng thuế đất online") -> đóng thuế đất online | FB3: =IFERROR(__xludf.DUMMYFUNCTION("""COMPUTED_VALUE"""),"https://techcombank.com/thong-tin/blog/due-diligence") -> https://techcombank.com/thong-tin/blog/due-diligence | FC3: =IFERROR(__xludf.DUMMYFUNCTION("""COMPUTED_VALUE"""),"nộp thuế đất online") -> nộp thuế đất online | FD3: =IFERROR(__xludf.DUMMYFUNCTION("""COMPUTED_VALUE"""),"https://techcombank.com/thong-tin/blog/giay-phep-kinh-doanh") -> https://techcombank.com/thong-tin/blog/giay-phep-kinh-doanh | FE3: =IFERROR(__xludf.DUMMYFUNCTION("""COMPUTED_VALUE"""),"cách nộp thuế đất online") -> cách nộp thuế đất online | FF3: =IFERROR(__xludf.DUMMYFUNCTION("""COMPUTED_VALUE"""),"https://techcombank.com/thong-tin/blog/dang-ky-kinh-doanh-la-gi") -> https://techcombank.com/thong-tin/blog/dang-ky-kinh-doanh-la-gi | FG3: =IFERROR(__xludf.DUMMYFUNCTION("""COMPUTED_VALUE"""),"đóng thuế đất online") -> đóng thuế đất online | FH3: =IFERROR(__xludf.DUMMYFUNCTION("""COMPUTED_VALUE"""),"https://techcombank.com/thong-tin/blog/thay-doi-dia-chi-ho-kinh-doanh") -> https://techcombank.com/thong-tin/blog/thay-doi-dia-chi-ho-kinh-doanh | FI3: =IFERROR(__xludf.DUMMYFUNCTION("""COMPUTED_VALUE"""),"nộp thuế đất online") -> nộp thuế đất online | FJ3: =IFERROR(__xludf.DUMMYFUNCTION("""COMPUTED_VALUE"""),"https://techcombank.com/thong-tin/blog/chuan-bi-cho-doanh-nghiep-khoi-nghiep-truoc-nhung-thay-doi-ve-thue") -> https://techcombank.com/thong-tin/blog/chuan-bi-cho-doanh-nghiep-khoi-nghiep-truoc-nhung-thay-doi-ve-thue | FK3: =IFERROR(__xludf.DUMMYFUNCTION("""COMPUTED_VALUE"""),"cách nộp thuế đất online") -> cách nộp thuế đất online | FL3: =IFERROR(__xludf.DUMMYFUNCTION("""COMPUTED_VALUE"""),"https://techcombank.com/thong-tin/blog/dieu-kien-vay-von-ngan-hang") -> https://techcombank.com/thong-tin/blog/dieu-kien-vay-von-ngan-hang | FM3: =IFERROR(__xludf.DUMMYFUNCTION("""COMPUTED_VALUE"""),"đóng thuế đất online") -> đóng thuế đất online | FN3: =IFERROR(__xludf.DUMMYFUNCTION("""COMPUTED_VALUE"""),"https://techcombank.com/thong-tin/blog/cach-tinh-thue-thu-nhap-doanh-nghiep") -> https://techcombank.com/thong-tin/blog/cach-tinh-thue-thu-nhap-doanh-nghiep | FO3: =IFERROR(__xludf.DUMMYFUNCTION("""COMPUTED_VALUE"""),"nộp thuế đất online") -> nộp thuế đất online | FP3: =IFERROR(__xludf.DUMMYFUNCTION("""COMPUTED_VALUE"""),"https://techcombank.com/thong-tin/blog/luu-y-khi-chuyen-doi-tu-ho-kinh-doanh-len-doanh-nghiep") -> https://techcombank.com/thong-tin/blog/luu-y-khi-chuyen-doi-tu-ho-kinh-doanh-len-doanh-nghiep | FQ3: =IFERROR(__xludf.DUMMYFUNCTION("""COMPUTED_VALUE"""),"cách nộp thuế đất online") -> cách nộp thuế đất online | FR3: =IFERROR(__xludf.DUMMYFUNCTION("""COMPUTED_VALUE"""),"https://techcombank.com/thong-tin/blog/cach-kiem-tra-tai-khoan-ngan-hang-cua-cong-ty") -> https://techcombank.com/thong-tin/blog/cach-kiem-tra-tai-khoan-ngan-hang-cua-cong-ty | FS3: =IFERROR(__xludf.DUMMYFUNCTION("""COMPUTED_VALUE"""),"đóng thuế đất online") -> đóng thuế đất online | FT3: =IFERROR(__xludf.DUMMYFUNCTION("""COMPUTED_VALUE"""),"https://techcombank.com/thong-tin/blog/thue-doanh-nghiep") -> https://techcombank.com/thong-tin/blog/thue-doanh-nghiep | FU3: =IFERROR(__xludf.DUMMYFUNCTION("""COMPUTED_VALUE"""),"nộp thuế đất online") -> nộp thuế đất online | FV3: =IFERROR(__xludf.DUMMYFUNCTION("""COMPUTED_VALUE"""),"https://techcombank.com/thong-tin/blog/dang-ky-ma-so-thue-ca-nhan") -> https://techcombank.com/thong-tin/blog/dang-ky-ma-so-thue-ca-nhan | FW3: =IFERROR(__xludf.DUMMYFUNCTION("""COMPUTED_VALUE"""),"cách nộp thuế đất online") -> cách nộp thuế đất online | FX3: =IFERROR(__xludf.DUMMYFUNCTION("""COMPUTED_VALUE"""),"https://techcombank.com/thong-tin/blog/cach-tao-ma-qr") -> https://techcombank.com/thong-tin/blog/cach-tao-ma-qr | FY3: =IFERROR(__xludf.DUMMYFUNCTION("""COMPUTED_VALUE"""),"đóng thuế đất online") -> đóng thuế đất online | FZ3: =IFERROR(__xludf.DUMMYFUNCTION("""COMPUTED_VALUE"""),"https://techcombank.com/thong-tin/blog/chuyen-doi-hoa-don-dien-tu") -> https://techcombank.com/thong-tin/blog/chuyen-doi-hoa-don-dien-tu | GA3: =IFERROR(__xludf.DUMMYFUNCTION("""COMPUTED_VALUE"""),"nộp thuế đất online") -> nộp thuế đất online | GB3: =IFERROR(__xludf.DUMMYFUNCTION("""COMPUTED_VALUE"""),"https://techcombank.com/thong-tin/blog/chinh-sach-thue-moi") -> https://techcombank.com/thong-tin/blog/chinh-sach-thue-moi | GC3: =IFERROR(__xludf.DUMMYFUNCTION("""COMPUTED_VALUE"""),"cách nộp thuế đất online") -> cách nộp thuế đất online | GD3: =IFERROR(__xludf.DUMMYFUNCTION("""COMPUTED_VALUE"""),"https://techcombank.com/thong-tin/blog/vay-the-chap-kinh-doanh") -> https://techcombank.com/thong-tin/blog/vay-the-chap-kinh-doanh | GE3: =IFERROR(__xludf.DUMMYFUNCTION("""COMPUTED_VALUE"""),"đóng thuế đất online") -> đóng thuế đất online | GF3: =IFERROR(__xludf.DUMMYFUNCTION("""COMPUTED_VALUE"""),"https://techcombank.com/thong-tin/blog/cach-su-dung-tai-khoan-cong-ty") -> https://techcombank.com/thong-tin/blog/cach-su-dung-tai-khoan-cong-ty | GG3: =IFERROR(__xludf.DUMMYFUNCTION("""COMPUTED_VALUE"""),"nộp thuế đất online") -> nộp thuế đất online | GH3: =IFERROR(__xludf.DUMMYFUNCTION("""COMPUTED_VALUE"""),"https://techcombank.com/thong-tin/blog/cach-tinh-thue-ho-kinh-doanh-nho-le") -> https://techcombank.com/thong-tin/blog/cach-tinh-thue-ho-kinh-doanh-nho-le | GI3: =IFERROR(__xludf.DUMMYFUNCTION("""COMPUTED_VALUE"""),"cách nộp thuế đất online") -> cách nộp thuế đất online | GJ3: =IFERROR(__xludf.DUMMYFUNCTION("""COMPUTED_VALUE"""),"https://techcombank.com/thong-tin/blog/nhung-ho-kinh-doanh-duoc-mien-thue") -> https://techcombank.com/thong-tin/blog/nhung-ho-kinh-doanh-duoc-mien-thue | GK3: =IFERROR(__xludf.DUMMYFUNCTION("""COMPUTED_VALUE"""),"đóng thuế đất online") -> đóng thuế đất online | GL3: =IFERROR(__xludf.DUMMYFUNCTION("""COMPUTED_VALUE"""),"https://techcombank.com/thong-tin/blog/lai-suat-vay-kinh-doanh") -> https://techcombank.com/thong-tin/blog/lai-suat-vay-kinh-doanh | GM3: =IFERROR(__xludf.DUMMYFUNCTION("""COMPUTED_VALUE"""),"nộp thuế đất online") -> nộp thuế đất online | GN3: =IFERROR(__xludf.DUMMYFUNCTION("""COMPUTED_VALUE"""),"https://techcombank.com/thong-tin/blog/bao-lanh-bao-hanh") -> https://techcombank.com/thong-tin/blog/bao-lanh-bao-hanh | GO3: =IFERROR(__xludf.DUMMYFUNCTION("""COMPUTED_VALUE"""),"cách nộp thuế đất online") -> cách nộp thuế đất online | GP3: =IFERROR(__xludf.DUMMYFUNCTION("""COMPUTED_VALUE"""),"https://techcombank.com/thong-tin/blog/bao-lanh-ngan-hang-infographic") -> https://techcombank.com/thong-tin/blog/bao-lanh-ngan-hang-infographic | GQ3: =IFERROR(__xludf.DUMMYFUNCTION("""COMPUTED_VALUE"""),"đóng thuế đất online") -> đóng thuế đất online | GR3: =IFERROR(__xludf.DUMMYFUNCTION("""COMPUTED_VALUE"""),"https://techcombank.com/thong-tin/blog/tin-dung-doanh-nghiep") -> https://techcombank.com/thong-tin/blog/tin-dung-doanh-nghiep | GS3: =IFERROR(__xludf.DUMMYFUNCTION("""COMPUTED_VALUE"""),"nộp thuế đất online") -> nộp thuế đất online | GT3: =IFERROR(__xludf.DUMMYFUNCTION("""COMPUTED_VALUE"""),"https://techcombank.com/thong-tin/blog/vay-bo-sung-von-luu-dong") -> https://techcombank.com/thong-tin/blog/vay-bo-sung-von-luu-dong | GU3: =IFERROR(__xludf.DUMMYFUNCTION("""COMPUTED_VALUE"""),"cách nộp thuế đất online") -> cách nộp thuế đất online | GV3: =IFERROR(__xludf.DUMMYFUNCTION("""COMPUTED_VALUE"""),"https://techcombank.com/thong-tin/blog/roa") -> https://techcombank.com/thong-tin/blog/roa | GW3: =IFERROR(__xludf.DUMMYFUNCTION("""COMPUTED_VALUE"""),"đóng thuế đất online") -> đóng thuế đất online | GX3: =IFERROR(__xludf.DUMMYFUNCTION("""COMPUTED_VALUE"""),"https://techcombank.com/thong-tin/blog/ebitda-la-gi") -> https://techcombank.com/thong-tin/blog/ebitda-la-gi | GY3: =IFERROR(__xludf.DUMMYFUNCTION("""COMPUTED_VALUE"""),"nộp thuế đất online") -> nộp thuế đất online | GZ3: =IFERROR(__xludf.DUMMYFUNCTION("""COMPUTED_VALUE"""),"https://techcombank.com/thong-tin/blog/vay-von-doanh-nghiep-nho") -> https://techcombank.com/thong-tin/blog/vay-von-doanh-nghiep-nho | HA3: =IFERROR(__xludf.DUMMYFUNCTION("""COMPUTED_VALUE"""),"cách nộp thuế đất online") -> cách nộp thuế đất online | HB3: =IFERROR(__xludf.DUMMYFUNCTION("""COMPUTED_VALUE"""),"https://techcombank.com/thong-tin/blog/von-luu-dong-la-gi") -> https://techcombank.com/thong-tin/blog/von-luu-dong-la-gi | HC3: =IFERROR(__xludf.DUMMYFUNCTION("""COMPUTED_VALUE"""),"đóng thuế đất online") -> đóng thuế đất online | HD3: =IFERROR(__xludf.DUMMYFUNCTION("""COMPUTED_VALUE"""),"https://techcombank.com/thong-tin/blog/bao-lanh-thuc-hien-hop-dong") -> https://techcombank.com/thong-tin/blog/bao-lanh-thuc-hien-hop-dong
